<?xml version="1.0" encoding="utf-8"?>

<robot name="melo">
    <material name="grey">
        <color rgba="0.8392 0.8666 0.847 1"/>
    </material>
    <material name="white">
        <color rgba="0.9392 0.9666 0.947 1"/>
    </material>
    <material name="blue">
        <color rgba="0.3392 0.3666 0.847 1"/>
    </material>

    <link name="track">
        <visual>
            <geometry>
                <mesh filename="./melo_meshes/track.stl" scale="0.001 0.001 0.001"/>
            </geometry>
            <material name="blue"/>
        </visual>
    </link>
    <link name="support">
        <visual>
            <origin rpy="0 0 0" xyz="0 -0.27 0.46"/>
            <geometry>
                <mesh filename="./melo_meshes/support.stl" scale="1 1 1"/>
            </geometry>
            <material name="white"/>
        </visual>
        <collision>
            <origin rpy="0 0 0" xyz="0 -0.27 0.6"/>
            <geometry>
                <box size="0.55 1.2 0.6" />
            </geometry>
        </collision>
    </link>
    <joint name="track_to_support" type="prismatic">
        <parent link="track" />
        <child link="support" />
        <origin xyz="0 0 0" />
        <axis xyz="0 1 0" />
        <!-- <limit effort="1" lower="-4" upper="4" velocity="100" /> -->
    </joint>
    <link name="base_link">
        <visual>
            <origin rpy="0 0 0" xyz="0 0 0" />
            <geometry>
                <mesh filename="./melo_meshes/base_link.stl" scale="1 1 1" />
            </geometry>
        </visual>
        <collision>
            <origin rpy="0 0 0" xyz="-0.05 0 0.1"/>
            <geometry>
                <box size="0.25 0.15 0.2" />
            </geometry>
        </collision>
    </link>
    <joint name="support_to_base" type="fixed">
        <parent link="support" />
        <child link="base_link" />
        <origin xyz="0 0 0.88"/>
    </joint>
    <link name="J1">
        <visual>
            <origin rpy="0 0 0" xyz="0 0 0" />
            <geometry>
                <mesh filename="./melo_meshes/J1.stl" scale="1 1 1" />
            </geometry>
            <material name="grey"/>
        </visual>
        <collision>
            <origin rpy="0 0 0" xyz="0 0 0.07"/>
            <geometry>
                <cylinder radius="0.1" length="0.2" />
            </geometry>
        </collision>
    </link>
    <joint name="joint_1" type="revolute">
        <parent link="base_link" />
        <child link="J1" />
        <origin rpy="0.000000 0.000000 0.000000" xyz="0.000000 0.000000 0.181500" />
        <axis xyz="-0.000000 -0.000000 1.000000" />
        <!-- <limit effort="1" lower="-2.96706" upper="2.96706" velocity="3.92699081698724" /> -->
    </joint>
    <link name="J2">
        <visual>
            <origin rpy="0 0 0" xyz="0 0 0" />
            <geometry>
                <mesh filename="./melo_meshes/J2.stl" scale="1 1 1" />
            </geometry>
            <material name="grey"/>
        </visual>
        <collision>
            <origin rpy="0 0 0" xyz="0 0 0.15"/>
            <geometry>
                <cylinder radius="0.08" length="0.35" />
            </geometry>
        </collision>
    </link>
    <joint name="joint_2" type="revolute">
        <parent link="J1" />
        <child link="J2" />
        <origin rpy="0.000000 0.000000 0.000000" xyz="0.000000 0.000000 0.163500" />
        <axis xyz="-0.000000 1.000000 -0.000000" />
        <!-- <limit effort="1" lower="-2.094395" upper="2.094395" velocity="2.61799387799149" /> -->
    </joint>
    <link name="J3">
        <visual>
            <origin rpy="0 0 0" xyz="0 0 0" />
            <geometry>
                <mesh filename="./melo_meshes/J3.stl" scale="1 1 1" />
            </geometry>
            <material name="grey"/>
        </visual>
        <collision>
            <origin rpy="0 0 0" xyz="0 0 0.08"/>
            <geometry>
                <cylinder radius="0.06" length="0.18" />
            </geometry>
        </collision>
    </link>
    <joint name="joint_3" type="revolute">
        <parent link="J2" />
        <child link="J3" />
        <origin rpy="0.000000 0.000000 0.000000" xyz="0.000000 0.000000 0.305000" />
        <axis xyz="-0.000000 1.000000 -0.000000" />
        <!-- <limit effort="1" lower="-2.181662" upper="2.70526" velocity="2.85832571599111" /> -->
    </joint>
    <link name="J4">
        <visual>
            <origin rpy="0 0 0" xyz="0 0 0" />
            <geometry>
                <mesh filename="./melo_meshes/J4.stl" scale="1 1 1" />
            </geometry>
            <material name="grey"/>
        </visual>
        <collision>
            <origin rpy="0 0 0" xyz="0 0 0.09"/>
            <geometry>
                <cylinder radius="0.05" length="0.12" />
            </geometry>
        </collision>
    </link>
    <joint name="joint_4" type="revolute">
        <parent link="J3" />
        <child link="J4" />
        <origin rpy="0.000000 0.000000 0.000000" xyz="-0.010000 0.000000 0.164500" />
        <axis xyz="-0.000000 -0.000000 1.000000" />
        <!-- <limit effort="1" lower="-4.712389" upper="4.712389" velocity="3.92699081698724" /> -->
    </joint>
    <link name="J5">
        <visual>
            <origin rpy="0 0 0" xyz="0 0 0" />
            <geometry>
                <mesh filename="./melo_meshes/J5.stl" scale="1 1 1" />
            </geometry>
            <material name="grey"/>
        </visual>
        <!-- <collision>
            <origin rpy="0 0 0" xyz="0 0 0.02"/>
            <geometry>
                <cylinder radius="0.03" length="0.05" />
            </geometry>
        </collision> -->
    </link>
    <joint name="joint_5" type="revolute">
        <parent link="J4" />
        <child link="J5" />
        <origin rpy="0.000000 0.000000 0.000000" xyz="0.000000 0.000000 0.135500" />
        <axis xyz="-0.000000 1.000000 -0.000000" />
        <!-- <limit effort="1" lower="-2.094395" upper="2.094395" velocity="3.02168853397778" /> -->
    </joint>
    <link name="J6">
        <visual>
            <origin rpy="0 0 0" xyz="0 0 0" />
            <geometry>
                <mesh filename="./melo_meshes/J6.stl" scale="1 1 1" />
            </geometry>
            <material name="grey"/>
        </visual>
        <visual>
            <origin rpy="-1.570 0 0" xyz="0 0 0" />
            <geometry>
                <mesh filename="./melo_meshes/eef_assy.stl" scale="1 1 1" />
            </geometry>
            <material name="grey"/>
        </visual>
        <collision>
            <origin rpy="-1.570 0 0" xyz="0 0 0.13" />
            <geometry>
                <box size="0.35 0.22 0.25" />
            </geometry>
        </collision>
    </link>
    <joint name="joint_6" type="revolute">
        <parent link="J5" />
        <child link="J6" />
        <origin rpy="0.000000 0.000000 0.000000" xyz="0.000000 0.000000 0.070000" />
        <axis xyz="-0.000000 -0.000000 1.000000" />
        <!-- <limit effort="1" lower="-6.283185" upper="6.283185" velocity="6.28318530717959" /> -->
    </joint>
</robot>
