<?xml version="1.0"?>

<robot name="box">

  <link name="box_link_1">

    <inertial>
      <origin xyz="0 0 0"/>
      <mass value="1" />
      <inertia ixx="1"  ixy="0"  ixz="0" iyy="1" iyz="0" izz="1" />
    </inertial>

    <visual>
      <origin xyz="0 0 0" />
      <geometry>
        <box size="0.05 0.05 0.05" />
      </geometry>
      <material>
        <color rgba="0 0 1 1" />
      </material>
    </visual>

    <collision>
      <origin xyz="0 0 0" />
      <geometry>
        <box size="0.01 0.01 0.01" />
      </geometry>
    </collision>
  </link>

  <!--
    It seems like Drake doesn't support a standard floating base,
    so we need to emulate the floating base for each body using two
    prismatic joints and one continuous revolute joint, as mentioned
    in Issue #3089 on Drake's GitHub.

    To support these various joints, we need dummy massless bodies to
    serve as intermediates
   -->
  <link name="dummy_1"></link>
  <link name="dummy_2"></link>

  <joint name="x" type="prismatic">
    <parent link="world" />
    <child link="dummy_1" />
    <origin xyz="0 0 0" />
    <axis xyz="1 0 0" />
  </joint>
  <joint name="y" type="prismatic">
    <parent link="dummy_1" />
    <child link="dummy_2" />
    <origin xyz="0 0 0" />
    <axis xyz="0 1 0" />
  </joint>
  <joint name="z" type="prismatic">
    <parent link="dummy_2" />
    <child link="box_link_1" />
    <origin xyz="0 0 0" />
    <axis xyz="0 0 1" />
  </joint>

</robot>