<?xml version="1.0" encoding="utf-8"?>
<!-- =================================================================================== -->
<!-- |    This document was autogenerated by xacro from rs010n.xacro                   | -->
<!-- |    EDITING THIS FILE BY HAND IS NOT RECOMMENDED                                 | -->
<!-- =================================================================================== -->
<robot name="kawasaki_rs010n">
  <!-- Properties -->
  <material name="kawasaki_white">
    <color rgba="0.8392 0.8666 0.847 1"/>
  </material>
  <!-- link list -->
  <link name="base_link">
    <visual>
      <geometry>
        <mesh filename="./rs010n_meshes/base.stl"/>
      </geometry>
      <material name="kawasaki_white"/>
    </visual>
    <!-- <collision>
      <origin rpy="0 0 0" xyz="0 0 0.08"/>
      <geometry>
        <cylinder length="0.22" radius="0.2"/>
      </geometry>
    </collision> -->
  </link>
  <link name="link_1_s">
    <visual>
      <geometry>
        <mesh filename="./rs010n_meshes/swivel.stl"/>
      </geometry>
      <material name="kawasaki_white"/>
    </visual>
    <collision>
      <origin rpy="0 0 0" xyz="0 0 -0.08"/>
      <geometry>
        <cylinder length="0.35" radius="0.22"/>
      </geometry>
    </collision>
  </link>
  <link name="link_2_l">
    <visual>
      <geometry>
        <mesh filename="./rs010n_meshes/bicep.stl"/>
      </geometry>
      <material name="kawasaki_white"/>
    </visual>
    <collision>
      <origin rpy="0 0 0" xyz="0.08 0 0.35"/>
      <geometry>
        <cylinder length="0.8" radius="0.12"/>
      </geometry>
    </collision>
  </link>
  <link name="link_3_u">
    <visual>
      <geometry>
        <mesh filename="./rs010n_meshes/elbow.stl"/>
      </geometry>
      <material name="kawasaki_white"/>
    </visual>
    <collision>
      <origin rpy="0 0 0" xyz="-0.015 0 0.05"/>
      <geometry>
        <cylinder length="0.28" radius="0.139"/>
      </geometry>
    </collision>
  </link>
  <link name="link_4_r">
    <visual>
      <geometry>
        <mesh filename="./rs010n_meshes/forearm.stl"/>
      </geometry>
      <material name="kawasaki_white"/>
    </visual>
    <collision>
      <origin rpy="0 0 0" xyz="0 0 -0.235"/>
      <geometry>
        <cylinder length="0.5" radius="0.07"/>
      </geometry>
    </collision>
  </link>
  <link name="link_5_b">
    <visual>
      <geometry>
        <mesh filename="./rs010n_meshes/wrist.stl"/>
      </geometry>
      <material name="kawasaki_white"/>
    </visual>
    <collision>
      <origin rpy="0 0 0" xyz="0 0 0.01"/>
      <geometry>
        <cylinder length="0.1" radius="0.04"/>
      </geometry>
    </collision>
  </link>
  <link name="link_6_t">
    <visual>
      <origin rpy="0 0 0" xyz="0 0 0"/>
      <geometry>
        <mesh filename="./rs010n_meshes/tool_mount.stl"/>
      </geometry>
      <material name="kawasaki_white"/>
    </visual>
    <visual>
      <origin rpy="0 0 0" xyz="0 0 -0.01"/>
      <geometry>
        <mesh filename="./component_meshes/gear.stl" scale="0.001"/>
      </geometry>
      <material name="kawasaki_white">
        <color rgba="0.8392 0.8666 0.847 1"/>
      </material>
    </visual>

    <collision>
      <origin rpy="0 0 0" xyz="0 0 -0.01"/>
      <geometry>
        <cylinder length="0.02" radius="0.043"/>
      </geometry>
    </collision>
    <collision>
      <origin rpy="0 0 0" xyz="0 0 0.01"/>
      <geometry>
        <cylinder length="0.04" radius="0.13"/>
      </geometry>
    </collision>
  </link>
  <link name="tool0"/>
  <!-- end of link list -->
  <!-- joint list -->
  <joint name="joint_1_s" type="revolute">
    <parent link="base_link"/>
    <child link="link_1_s"/>
    <origin rpy="0 0 0" xyz="0 0 0.430"/>
    <axis xyz="0 0 1"/>
    <!-- Efforts are not accurate! -->
    <limit effort="1000.0" lower="-3.142" upper="3.142" velocity="4.363"/>
  </joint>
  <joint name="joint_2_l" type="revolute">
    <parent link="link_1_s"/>
    <child link="link_2_l"/>
    <origin rpy="0 0 0" xyz="0.0 0.1 0.0"/>
    <axis xyz="-1 0 0"/>
    <!-- Efforts are not accurate! -->
    <limit effort="1000.0" lower="-1.833" upper="2.531" velocity="4.363"/>
  </joint>
  <joint name="joint_3_u" type="revolute">
    <parent link="link_2_l"/>
    <child link="link_3_u"/>
    <origin rpy="0 0 0" xyz="0 0 0.65"/>
    <axis xyz="1 0 0"/>
    <!-- Efforts are not accurate! -->
    <limit effort="1000.0" lower="-2.845" upper="2.618" velocity="3.752"/>
  </joint>
  <joint name="joint_4_r" type="revolute">
    <parent link="link_3_u"/>
    <child link="link_4_r"/>
    <origin rpy="0 0 0" xyz="0.00 0 0.7"/>
    <axis xyz="0 0 1"/>
    <!-- Efforts are not accurate! -->
    <limit effort="1000.0" lower="-4.712" upper="4.712" velocity="6.370"/>
  </joint>
  <joint name="joint_5_b" type="revolute">
    <parent link="link_4_r"/>
    <child link="link_5_b"/>
    <origin rpy="0 0 0" xyz="0 0 0"/>
    <axis xyz="1 0 0"/>
    <!-- Efforts are not accurate! -->
    <limit effort="1000.0" lower="-2.531" upper="2.531" velocity="6.632"/>
  </joint>
  <joint name="joint_6_t" type="revolute">
    <parent link="link_5_b"/>
    <child link="link_6_t"/>
    <origin rpy="0 0 0" xyz="0 0 0.085"/>
    <axis xyz="0 0 1"/>
    <!-- Efforts are not accurate! -->
    <limit effort="1000.0" lower="-6.283" upper="6.283" velocity="12.217"/>
  </joint>
  <joint name="joint_6_t-tool0" type="fixed">
    <origin rpy="3.1415926 -1.570796 0" xyz="0.100 0 0"/>
    <parent link="link_6_t"/>
    <child link="tool0"/>
  </joint>
  <!-- end of joint list -->
</robot>
