<?xml version="1.0" encoding="utf-8" ?>
<!-- This URDF was automatically created by SolidWorks to URDF Exporter! Originally created by Stephen Brawner (brawner@gmail.com) 
     Commit Version: 1.5.1-0-g916b5db  Build Version: 1.5.7152.31018
     For more information, please see http://wiki.ros.org/sw_urdf_exporter 

This URDF was sourced from https://git.barrett.com/software/barrett-ros2-pkg/-/tree/devel
 -->
<robot name="wam7dof">
    <link name="base_link">
        
<inertial>
            <origin xyz="3.40104668810678E-05 0.0736066059361038 -0.0587577266799806" rpy="0 0 3.14" />
            <mass value="13.5476126893973" />
            <inertia ixx="0.156470957074821" ixy="-4.03291630164832E-05" ixz="4.63998145785361E-05" iyy="0.214731752462203" iyz="0.00513845865911244" izz="0.108286175637366" />
        </inertial>

        <visual>
            <origin xyz="0 0 0" rpy="0 0 0" />
            <geometry>
                <!-- <box size="0.3 0.35 0.15" /> -->
                <mesh filename="./wam_meshes/base_link.STL" />
            </geometry>
            <material name="">
                <color rgba="0.792156862745098 0.819607843137255 0.933333333333333 1" />
            </material>
        </visual>
        <collision>
            <origin xyz="0 0.04 0.08" rpy="0 0 0" />
            <geometry>
                <box size="0.3 0.37 0.17" />
            </geometry>
        </collision>
    </link>
    <link name="FirstLink">
        
        <inertial>
            <origin xyz="-0.139999974600984 0.264881717494166 3.04922795226637E-09" rpy="0 0 0" />
            <mass value="0.03731551398704" />
            <inertia ixx="0.276162321852689" ixy="5.2006100830383E-08" ixz="7.60373820597545E-08" iyy="0.237968754825239" iyz="3.7940385825581E-09" izz="0.145688610159368" />
        </inertial>

        <visual>
            <origin xyz="0 0 0" rpy="0 0 0" />
            <geometry>
                <mesh filename="./wam_meshes/FirstLink.STL" />
            </geometry>
            <material name="">
                <color rgba="0.796078431372549 0.796078431372549 0.752941176470588 1" />
            </material>
        </visual>

        <collision>
            <origin xyz="0 0.12 0" rpy="0 0 0" />
            <geometry>
                <box size="0.17 0.24 0.37" />
            </geometry>
        </collision>
    </link>
    <joint name="q1" type="revolute">
        <origin xyz="0 0 0.16" rpy="1.5708 0 1.5708" />
        <parent link="base_link" />
        <child link="FirstLink" />
        <axis xyz="0 1 0" />
        <limit lower="-2.6" upper="2.6" effort="40" velocity="10" />
    </joint>
    <link name="SecondLink">
        
        <inertial>
            <origin xyz="-3.30733566011414E-06 0.0504592578779878 -1.93867229948091E-05" rpy="0 0 0" />
            <mass value="0.061755485547077" />
            <inertia ixx="0.00258552588913393" ixy="-1.52178232460015E-08" ixz="-4.72455503361288E-08" iyy="0.00186310872414462" iyz="3.58033312144846E-08" izz="0.00227630686304741" />
        </inertial>

        <visual>
            <origin xyz="0 0 0" rpy="0 0 0" />
            <geometry>
                <mesh filename="./wam_meshes/SecondLink.STL" />
            </geometry>
            <material name="">
                <color rgba="0.796078431372549 0.796078431372549 0.752941176470588 1" />
            </material>
        </visual>

        <collision>
            <origin xyz="0 0.02 0" rpy="0 0 0" />
            <geometry>
                <box size="0.13 0.17 0.15" />
            </geometry>
        </collision>
    </link>
    <joint name="q2" type="revolute">
        <origin xyz="0 0.186 0" rpy="3.1416 -1.5708 3.1416" />
        <parent link="FirstLink" />
        <child link="SecondLink" />
        <axis xyz="1 0 0" />
        <limit lower="-2" upper="2" effort="40" velocity="10" />
    </joint>
    <link name="ThirdLink">
        
<inertial>
            <origin xyz="9.06096997991331E-06 0.79471468339664 -0.0130869016439971" rpy="0 0 0" />
            <mass value="0.038872635233449" />
            <inertia ixx="0.030078978512962" ixy="-1.13635301361627E-06" ixz="2.68391541479368E-07" iyy="0.00292730712291074" iyz="0.0017695664165155" izz="0.0304265922248273" />
        </inertial>

        <visual>
            <origin xyz="0 0 0" rpy="0 0 0" />
            <geometry>
                <mesh filename="./wam_meshes/ThirdLink.STL" />
            </geometry>
            <material name="">
                <color rgba="0.898039215686275 0.917647058823529 0.929411764705882 1" />
            </material>
        </visual>

        <collision>
            <origin xyz="0 0.68 0" rpy="0 0 0" />
            <geometry>
                <box size="0.1 0.45 0.1" />
            </geometry>
        </collision>
    </link>
    <joint name="q3" type="revolute">
        <origin xyz="0 -0.346 0" rpy="3.1416 0 3.1416" />
        <parent link="SecondLink" />
        <child link="ThirdLink" />
        <axis xyz="0 1 0" />
        <limit lower="-2.8" upper="2.8" effort="40" velocity="10" />
    </joint>
    <link name="FourthLink">
        
        <inertial>
            <origin xyz="-0.000129381758547355 0.0430627866930996 0.150035156293387" rpy="0 0 0" />
            <mass value="0.017270635973466" />
            <inertia ixx="0.0144861530368099" ixy="-7.35011796438337E-08" ixz="1.46278041404691E-05" iyy="0.0143994232215456" iyz="-0.000349637115920233" izz="0.00465327086275674" />
        </inertial>

        <visual>
            <origin xyz="0 0 0" rpy="0 0 0" />
            <geometry>
                <mesh filename="./wam_meshes/FourthLink.STL" />
            </geometry>
            <material name="">
                <color rgba="0.666666666666667 0.63921568627451 0.556862745098039 1" />
            </material>
        </visual>

        <collision>
            <origin xyz="0 0.05 0.15" rpy="0 0 0" />
            <geometry>
                <box size="0.1 0.1 0.25" />
            </geometry>
        </collision>
    </link>
    <joint name="q4" type="revolute">
        <origin xyz="0 0.896 -0.045" rpy="1.5708 0 3.1416" />
        <parent link="ThirdLink" />
        <child link="FourthLink" />
        <axis xyz="1 0 0" />
        <limit lower="-0.9" upper="3.1" effort="40" velocity="10" />
    </joint>
    <link name="FifthLink">
        
<inertial>
            <origin xyz="6.78196069913216E-14 0.0187615886070163 -1.8990032765365E-08" rpy="0 0 0" />
            <mass value="0.0149005443008753" />
            <inertia ixx="8.68246260680858E-05" ixy="8.32563149485477E-12" ixz="9.56774172507725E-11" iyy="8.70844273808338E-05" iyz="8.15648112659227E-11" izz="6.71124003197135E-05" />
        </inertial>

        <visual>
            <origin xyz="0 0 0" rpy="0 0 0" />
            <geometry>
                <mesh filename="./wam_meshes/FifthLink.STL" />
            </geometry>
            <material name="">
                <color rgba="0.47843137254902 0.454901960784314 0.345098039215686 1" />
            </material>
        </visual>

        <collision>
            <origin xyz="0 0.02 0" rpy="0 0 0" />
            <geometry>
                <box size="0.04 0.07 0.07" />
            </geometry>
        </collision>
    </link>
    <joint name="q5" type="revolute">
        <origin xyz="0 0.045 0.2723" rpy="1.5708 0 0" />
        <parent link="FourthLink" />
        <child link="FifthLink" />
        <axis xyz="0 1 0" />
        <limit lower="-4.76" upper="1.24" effort="40" velocity="10" />
    </joint>
    <link name="SixthLink">
        
        <inertial>
            <origin xyz="-0.0139658979390116 0.0242366974396766 9.86247031466266E-08" rpy="0 0 0" />
            <mass value="0.0506696185792322" />
            <inertia ixx="0.000369379806854581" ixy="1.50400439239954E-05" ixz="-2.41001577391907E-09" iyy="0.000619056939139963" iyz="1.91499423781416E-10" izz="0.000747159541140852" />
        </inertial>

        <visual>
            <origin xyz="0 0 0" rpy="0 0 0" />
            <geometry>
                <mesh filename="./wam_meshes/SixthLink.STL" />
            </geometry>
            <material name="">
                <color rgba="0.898039215686275 0.917647058823529 0.929411764705882 1" />
            </material>
        </visual>

        <collision>
            <origin xyz="-0.015 0.02 0" rpy="0 0 0" />
            <geometry>
                <box size="0.1 0.06 0.05" />
            </geometry>
        </collision>
    </link>
    <joint name="q6" type="revolute">
        <origin xyz="0 0.02721 0" rpy="0 0 0" />
        <parent link="FifthLink" />
        <child link="SixthLink" />
        <axis xyz="1 0 0" />
        <limit lower="-1.6" upper="1.6" effort="40" velocity="10" />
    </joint>
    <link name="SeventhLink">
        
        <inertial>
            <origin xyz="-2.76116528402228E-16 0.00888734044750605 1.73472347597681E-18" rpy="0 0 0" />
            <mass value="0.0991011928366143" />
            <inertia ixx="6.46940974881037E-05" ixy="-7.72224623395982E-21" ixz="-3.76158192263132E-36" iyy="0.000127725203661566" iyz="2.6027372930156E-21" izz="6.46940974881037E-05" />
        </inertial>

        <visual>
            <origin xyz="0 0 0" rpy="0 0 0" />
            <geometry>
                <mesh filename="./wam_meshes/SeventhLink.STL" />
            </geometry>
            <material name="">
                <color rgba="0.831372549019608 0.847058823529412 0.858823529411765 1" />
            </material>
        </visual>

        <collision>
            <origin xyz="0 0.01 0" rpy="1.571 1.571 0" />
            <geometry>
                <cylinder length="0.02" radius="0.045"/>
            </geometry>
        </collision>
    </link>
    <joint name="q7" type="revolute">
        <origin xyz="-0.006251 0.04795 0" rpy="0 1.5708 0" />
        <parent link="SixthLink" />
        <child link="SeventhLink" />
        <axis xyz="0 1 0" />
        <limit lower="-3" upper="3" effort="40" velocity="10" />
    </joint>
</robot>
